Workbook
Name _AccountService: Profile!$A$3163
Name _ActionInfo: Profile!$A$1736
Name _Assembly: Profile!$A$1987
Name _AttributeRegistry: Profile!$A$1183
Name _BootOption: Profile!$A$20
Name _Chassis: Profile!$A$1990
Name _Common_Properties: Profile!$A$1258
Name _ComputerSystem: Profile!$A$21
Name _Drive: Profile!$A$2087
Name _Endpoint: Profile!#REF!
Name _EthernetInterface: Profile!$A$1358
Name _Event: Profile!$A$601
Name _EventDestination: Profile!$A$629
Name _EventService: Profile!$A$653
Name _ExternalAccountProvider: Profile!$A$3240
Name _Hlk524428920: Profile!$A$637
Name _Hlk524430808: Profile!$A$3109
Name _HostInterface: Profile!$A$969
Name _Identifier: Profile!$A$3141
Name _IP_Address: Profile!$A$1435
Name _Job: Profile!$A$1751
Name _JobService: Profile!$A$1789
Name _JSONSchemaFile: Profile!$A$1275
Name _Location: Profile!$A$2159
Name _LogEntry: Profile!$A$695
Name _LogService: Profile!$A$726
Name _MaintenanceWindow: Profile!$A$1816
Name _Manager: Profile!$A$1011
Name _ManagerAccount: Profile!$A$3241
Name _ManagerNetworkProtocol: Profile!$A$1470
Name _Memory: Profile!#REF!
Name _MemoryChunks: Profile!$A$263
Name _MemoryDomain: Profile!$A$264
Name _MemoryMetrics_1: Profile!$A$265
Name _Message: Profile!$A$1291
Name _MessageRegistry: Profile!$A$1305
Name _MessageRegistryFile: Profile!$A$1316
Name _MetricDefinition: Profile!$A$747
Name _MetricReport: Profile!$A$793
Name _MetricReportDefinition: Profile!$A$811
Name _NetworkAdapter_1: Profile!$A$2809
Name _NetworkDeviceFunction: Profile!$A$1538
Name _NetworkInterface: Profile!$A$1623
Name _NetworkPort: Profile!$A$1643
Name _OperationApplyTimeSupport: Profile!$A$1826
Name _PCIeDevice: Profile!$A$2864
Name _PCIeFunction: Profile!$A$300
Name _PCIeSlots: Profile!$A$2895
Name _Port: Profile!$A$1685
Name _Power_1: Profile!$A$2920
Name _PreferredApplyTime: Profile!$A$1839
Name _PrivilegeRegistry: Profile!$A$3261
Name _Processor: Profile!$A$336
Name _Redundancy: Profile!$A$1851
Name _Ref534807854: Profile!#REF!
Name _Ref534808450: Profile!$A$266
Name _Ref534808663: Profile!$A$301
Name _Ref534808775: Profile!$A$337
Name _Ref534809695: Profile!$A$417
Name _Ref534811760: Profile!$A$22

Sheet Instructions
A2: Copy and paste entire Word Doc Resource Tables sections starting at Cell A3
A3: Select Profile (Red Box)
A4: Copy Combined colum into Word Doc below the profile metadata
B5: Substitutions
C6: <tab> with ^t
C7: <cr> with ^p
C8: ^p^p with ^p (many times)
A9: Clean up

Sheet Profile
AQ1: Change Log - V3.x | AR1: Change Log - V3.x | AS1: Change Log - V2.x | AT1: Change Log - v2.1 | AU1: Change Log - V2
A2: PASTE red outlined box to opaf_sm_dump.txt for profile json generation | I2: V1 | J2: V2 | K2: V3 | L2: OPCUA | AM2: 1000 | AN2: 1300 | AO2: 1600 | AP2: CRQ Increment
A3: ProfileName | C3: OSM-Redfish | E3: OSM-RedfishBMC | G3: OSM-RedfishDCN | I3: Y | J3: Y | K3: Y | L3: OSM-OPC-UA | M3: Special Reqs | Z3: Category | AA3: Parent | AB3: Type | AC3: Permissions | AD3: LongDescription | AE3: Nullable | AF3: Constraints | AG3: AutoExpand | AH3: Reference | AI3: ContainsTarget | AJ3: IsBound | AK3: Singular | AL3: Units | AP3: 4 | AV3: =IF(A3<>"",IF(T3<>"",IF(LEFT(R3,3)="Has",IF(TRIM(A3)<>T3,"ERROR","OK"),""),""),"")
A4: ProfilePurpose | B4: These are the purpose descriptions that will go into each profile doc | C4: Specifies the management requirements for the Redfish profile on O-PAS compliant platforms without a BMC. This profile is designed to run in the host operating system (in-band). | E4: Specifies the management requirements for the Redfish profile on O-PAS compliant platforms with a BMC. | G4: Specifies the management requirements for the Redfish profile on O-PAS compliant platforms with OperatingSystem and DistributedControlNode support. This profile is designed to run in the host operating system (in-band). | I4: Y | J4: Y | K4: Y | L4: Specifies the mapped resources and properties between the O-PAS Redfish profile superset and OPC UA. | AU4: A | AV4: =IF(A4<>"",IF(T4<>"",IF(LEFT(R4,3)="Has",IF(TRIM(A4)<>T4,"ERROR","OK"),""),""),"")
E5: n | AV5: =IF(A5<>"",IF(T5<>"",IF(LEFT(R5,3)="Has",IF(TRIM(A5)<>T5,"ERROR","OK"),""),""),"")
A6: 1.1.1.1 Bios | I6: Y | J6: Y | K6: Y | L6: NoMap | AV6: =IF(A6<>"",IF(T6<>"",IF(LEFT(R6,3)="Has",IF(TRIM(A6)<>T6,"ERROR","OK"),""),""),"")
A7: The BIOS AttributeRegistry describes the system-specific BIOS attributes and actions for changing the BIOS settings. Changes to the BIOS typically require a system reset before they take effect. | I7: Y | J7: Y | K7: Y | L7: NoMap | AV7: =IF(A7<>"",IF(T7<>"",IF(LEFT(R7,3)="Has",IF(TRIM(A7)<>T7,"ERROR","OK"),""),""),"")
A8: Table 9: O-PAS Profile Map for the Redfish Bios Resource | I8: Y | J8: Y | K8: Y | L8: NoMap | AA8: Resource | AB8: Version | AC8: Description | AV8: =IF(A8<>"",IF(T8<>"",IF(LEFT(R8,3)="Has",IF(TRIM(A8)<>T8,"ERROR","OK"),""),""),"")
A9: Bios (1.0.4) | C9: Profile | I9: Y | L9: NoMap | AA9: =LEFT($A9,FIND(" ",$A9)-1) -> Bios | AB9: =MID($A9,FIND("(",$A9)+1,LEN($A9)-FIND("(",$A9)-1) -> 1.0.4 | AC9: =A7 -> The BIOS AttributeRegistry describes the system-specific BIOS attributes and actions for changing the BIOS settings. Changes to the BIOS typically require a system reset before they take effect. | AV9: =IF(A9<>"",IF(T9<>"",IF(LEFT(R9,3)="Has",IF(TRIM(A9)<>T9,"ERROR","OK"),""),""),"")
C10: OSM-Redfish | E10: OSM-RedfishBMC | G10: OSM-RedfishDCN | I10: Y | L10: NoMap | AA10: Resource | AB10: Version | AC10: Description | AV10: =IF(A10<>"",IF(T10<>"",IF(LEFT(R10,3)="Has",IF(TRIM(A10)<>T10,"ERROR","OK"),""),""),"")
A11: Bios (1.0.6) | C11: Profile | J11: Y | K11: Y | L11: NoMap | AA11: =LEFT($A11,FIND(" ",$A11)-1) -> Bios | AB11: =MID($A11,FIND("(",$A11)+1,LEN($A11)-FIND("(",$A11)-1) -> 1.0.6 | AC11: =AC9 -> The BIOS AttributeRegistry describes the system-specific BIOS attributes and actions for changing the BIOS settings. Changes to the BIOS typically require a system reset before they take effect. | AV11: =IF(A11<>"",IF(T11<>"",IF(LEFT(R11,3)="Has",IF(TRIM(A11)<>T11,"ERROR","OK"),""),""),"")
C12: OSM-Redfish | E12: OSM-RedfishBMC | G12: OSM-RedfishDCN | J12: Y | K12: Y | L12: NoMap | AM12: =C12 -> OSM-Redfish | AN12: =E12 -> OSM-RedfishBMC | AO12: =G12 -> OSM-RedfishDCN | AV12: =IF(A12<>"",IF(T12<>"",IF(LEFT(R12,3)="Has",IF(TRIM(A12)<>T12,"ERROR","OK"),""),""),"")
A13: ResourceRequirement | E13: R | I13: Y | J13: Y | K13: Y | L13: NoMap | AM13: =IF(C13<>"","CRQ-P5-"&(AM$2+$AP13*$AP$3),"") | AN13: =IF(E13<>"","CRQ-P5-"&(AN$2+$AP13*$AP$3),"") -> CRQ-P5-1316 | AO13: =IF(G13<>"","CRQ-P5-"&(AO$2+$AP13*$AP$3),"") | AP13: 4 | AV13: =IF(A13<>"",IF(T13<>"",IF(LEFT(R13,3)="Has",IF(TRIM(A13)<>T13,"ERROR","OK"),""),""),"")
A14: Resource MinVersion | C14: =MID($A9,FIND("(",$A9)+1,5) -> 1.0.4 | E14: 1.0.2 | G14: =MID($A9,FIND("(",$A9)+1,5) -> 1.0.4 | I14: Y | J14: Y | K14: Y | L14: NoMap | AV14: =IF(A14<>"",IF(T14<>"",IF(LEFT(R14,3)="Has",IF(TRIM(A14)<>T14,"ERROR","OK"),""),""),"")
A15: Property | B15: Description | C15: Read | D15: Write | E15: Read | F15: Write | G15: Read | H15: Write | I15: Y | J15: Y | K15: Y | L15: NoMap | AV15: =IF(A15<>"",IF(T15<>"",IF(LEFT(R15,3)="Has",IF(TRIM(A15)<>T15,"ERROR","OK"),""),""),"")
A16: Actions | B16: The available actions for this resource. | E16: R | I16: Y | J16: Y | K16: Y | L16: NoMap | AV16: =IF(A16<>"",IF(T16<>"",IF(LEFT(R16,3)="Has",IF(TRIM(A16)<>T16,"ERROR","OK"),""),""),"")
A17: #Bios.ChangePassword | B17: This action is used to change the BIOS passwords. | E17: R | I17: Y | J17: Y | K17: Y | L17: NoMap | AV17: =IF(A17<>"",IF(T17<>"",IF(LEFT(R17,3)="Has",IF(TRIM(A17)<>T17,"ERROR","OK"),""),""),"")
A18: #Bios.ResetBios | B18: This action is used to reset the BIOS attributes to default. | E18: R | I18: Y | J18: Y | K18: Y | L18: NoMap | AV18: =IF(A18<>"",IF(T18<>"",IF(LEFT(R18,3)="Has",IF(TRIM(A18)<>T18,"ERROR","OK"),""),""),"")
A19: AttributeRegistry | B19: The Resource ID of the AttributeRegistry that has the system-specific information about a BIOS resource. | I19: Y | J19: Y | K19: Y | L19: NoMap | AV19: =IF(A19<>"",IF(T19<>"",IF(LEFT(R19,3)="Has",IF(TRIM(A19)<>T19,"ERROR","OK"),""),""),"")
A20: Attributes | B20: The list of BIOS attributes specific to the manufacturer or provider. | E20: M | I20: Y | J20: Y | K20: Y | L20: NoMap | AV20: =IF(A20<>"",IF(T20<>"",IF(LEFT(R20,3)="Has",IF(TRIM(A20)<>T20,"ERROR","OK"),""),""),"")
A21: Bios URIs | I21: Y | J21: Y | K21: Y | L21: NoMap | AV21: =IF(A21<>"",IF(T21<>"",IF(LEFT(R21,3)="Has",IF(TRIM(A21)<>T21,"ERROR","OK"),""),""),"")
A22: /redfish/v1/Systems/{ComputerSystemId}/Bios | I22: Y | J22: Y | K22: Y | L22: NoMap | AV22: =IF(A22<>"",IF(T22<>"",IF(LEFT(R22,3)="Has",IF(TRIM(A22)<>T22,"ERROR","OK"),""),""),"")
AV23: =IF(A23<>"",IF(T23<>"",IF(LEFT(R23,3)="Has",IF(TRIM(A23)<>T23,"ERROR","OK"),""),""),"")
A24: 1.1.1.2 BootOption | I24: Y | J24: Y | K24: Y | AV24: =IF(A24<>"",IF(T24<>"",IF(LEFT(R24,3)="Has",IF(TRIM(A24)<>T24,"ERROR","OK"),""),""),"")
A25: The BootOption resource represents the properties of a bootable device available in the system. | I25: Y | J25: Y | K25: Y | AV25: =IF(A25<>"",IF(T25<>"",IF(LEFT(R25,3)="Has",IF(TRIM(A25)<>T25,"ERROR","OK"),""),""),"")
A26: BootOption is not used in O-PAS system management profiles. | I26: Y | J26: Y | K26: Y | AV26: =IF(A26<>"",IF(T26<>"",IF(LEFT(R26,3)="Has",IF(TRIM(A26)<>T26,"ERROR","OK"),""),""),"")
AV27: =IF(A27<>"",IF(T27<>"",IF(LEFT(R27,3)="Has",IF(TRIM(A27)<>T27,"ERROR","OK"),""),""),"")
A28: 1.1.1.3 ComputerSystemCollection | I28: Y | J28: Y | K28: Y | AV28: =IF(A28<>"",IF(T28<>"",IF(LEFT(R28,3)="Has",IF(TRIM(A28)<>T28,"ERROR","OK"),""),""),"")
A29: A ComputerSystemCollection is a collection of ComputerSystem Resources | I29: Y | J29: Y | K29: Y | AV29: =IF(A29<>"",IF(T29<>"",IF(LEFT(R29,3)="Has",IF(TRIM(A29)<>T29,"ERROR","OK"),""),""),"")
A30: Table 10: O-PAS Profile Map for the Redfish ComputerSystemCollection Resource | I30: Y | J30: Y | K30: Y | AA30: Resource | AB30: Version | AC30: Description | AV30: =IF(A30<>"",IF(T30<>"",IF(LEFT(R30,3)="Has",IF(TRIM(A30)<>T30,"ERROR","OK"),""),""),"")
A31: ComputerSystemCollection () | C31: Profile | I31: Y | J31: Y | K31: Y | AA31: =LEFT($A31,FIND(" ",$A31)-1) -> ComputerSystemCollection | AB31: =MID($A31,FIND("(",$A31)+1,LEN($A31)-FIND("(",$A31)-1) | AC31: =A29 -> A ComputerSystemCollection is a collection of ComputerSystem Resources | AV31: =IF(A31<>"",IF(T31<>"",IF(LEFT(R31,3)="Has",IF(TRIM(A31)<>T31,"ERROR","OK"),""),""),"")
C32: OSM-Redfish | E32: OSM-RedfishBMC | G32: OSM-RedfishDCN | I32: Y | J32: Y | K32: Y | AV32: =IF(A32<>"",IF(T32<>"",IF(LEFT(R32,3)="Has",IF(TRIM(A32)<>T32,"ERROR","OK"),""),""),"")
A33: ResourceRequirement | C33: M | E33: M | G33: M | I33: Y | J33: Y | K33: Y | M33: MinCount1 | AV33: =IF(A33<>"",IF(T33<>"",IF(LEFT(R33,3)="Has",IF(TRIM(A33)<>T33,"ERROR","OK"),""),""),"")
A34: Property | B34: Description | C34: Read | D34: Write | E34: Read | F34: Write | G34: Read | H34: Write | I34: Y | J34: Y | K34: Y | AV34: =IF(A34<>"",IF(T34<>"",IF(LEFT(R34,3)="Has",IF(TRIM(A34)<>T34,"ERROR","OK"),""),""),"")
A35: Members | B35: Collection of ComputerSystems associated with this system. Contains a link to a resource. | I35: Y | J35: Y | K35: Y | AV35: =IF(A35<>"",IF(T35<>"",IF(LEFT(R35,3)="Has",IF(TRIM(A35)<>T35,"ERROR","OK"),""),""),"")
A36: @odata.id | B36: A link to the collection of ComputerSystems | I36: Y | J36: Y | K36: Y | AV36: =IF(A36<>"",IF(T36<>"",IF(LEFT(R36,3)="Has",IF(TRIM(A36)<>T36,"ERROR","OK"),""),""),"")
A37: ComputerSystemCollection URIs | I37: Y | J37: Y | K37: Y | AV37: =IF(A37<>"",IF(T37<>"",IF(LEFT(R37,3)="Has",IF(TRIM(A37)<>T37,"ERROR","OK"),""),""),"")
A38: /redfish/v1/Systems | I38: Y | J38: Y | K38: Y | AV38: =IF(A38<>"",IF(T38<>"",IF(LEFT(R38,3)="Has",IF(TRIM(A38)<>T38,"ERROR","OK"),""),""),"")
AV39: =IF(A39<>"",IF(T39<>"",IF(LEFT(R39,3)="Has",IF(TRIM(A39)<>T39,"ERROR","OK"),""),""),"")
A40: 1.1.1.3 ComputerSystem | I40: Y | J40: Y | K40: Y | AV40: =IF(A40<>"",IF(T40<>"",IF(LEFT(R40,3)="Has",IF(TRIM(A40)<>T40,"ERROR","OK"),""),""),"")
...

Sheet Enum
A1: OSM-Redfish
A2: OSM-RedfishBMC
A3: OSM-RedfishDCN

Sheet Sheet1
A1: Accuracy number read-only
A2: (null)
A3: Estimated percent error of measured vs. actual values.
A4: Actions { object The available actions for this resource.
A5: #Sensor.ResetStatistics { }
A6: }
A7: object This action is used to reset statistics related to this sensor.
A8: For more information, see the Action Details section below.
A9: AdjustedMaxAllowableOperatingValue number read-only
A10: (null)
A11: Adjusted maximum allowable operating value for this equipment based on the current
A12: environmental conditions present.
... A195: See VoltageType in Property Details, below, for the possible values of this property.

Sheet Sheet2
A1: =ROW() -> 1 | B1: =Profile!A1 -> 0 | C1: =Profile!AP3 -> 4 | D1: =IF(Profile!C1="Profile",IF(Profile!A3="ResourceRequirement","OK","XXX"),"XXX") -> XXX | G1: 11 | H1: Bios (1.0.6) | I1: 4 | J1: OK
A2: =ROW() -> 2 | B2: =Profile!A2 -> PASTE red outlined box to opaf_sm_dump.txt for profile json generation | C2: =Profile!AP4 -> 0 | D2: =IF(Profile!C2="Profile",IF(Profile!A4="ResourceRequirement","OK","XXX"),"XXX") -> XXX | G2: 45 | H2: ComputerSystem (1.7.0) | I2: 9 | J2: OK
A3: =ROW() -> 3 | B3: =Profile!A3 -> ProfileName | C3: =Profile!AP5 -> 0 | D3: =IF(Profile!C3="Profile",IF(Profile!A5="ResourceRequirement","OK","XXX"),"XXX") -> XXX | G3: 168 | H3: Memory (1.7.1) | I3: 29 | J3: OK
A4: =ROW() -> 4 | B4: =Profile!A4 -> ProfilePurpose | C4: =Profile!AP6 -> 0 | D4: =IF(Profile!C4="Profile",IF(Profile!A6="ResourceRequirement","OK","XXX"),"XXX") -> XXX | G4: 271 | H4: MemoryMetrics (1.1.5) | I4: 30 | J4: OK
A5: =ROW() -> 5 | B5: =Profile!A5 -> 0 | C5: =Profile!AP7 -> 0 | D5: =IF(Profile!C5="Profile",IF(Profile!A7="ResourceRequirement","OK","XXX"),"XXX") -> XXX | G5: 305 | H5: PCIeFunction (1.2.2) | I5: 44 | J5: OK
A6: =ROW() -> 6 | B6: =Profile!A6 -> 1.1.1.1 Bios | C6: =Profile!AP8 -> 0 | D6: =IF(Profile!C6="Profile",IF(Profile!A8="ResourceRequirement","OK","XXX"),"XXX") -> XXX | G6: 342 | H6: Processor (1.5.0) | I6: 47 | J6: OK
A7: =ROW() -> 7 | B7: =Profile!A7 -> The BIOS AttributeRegistry describes the system-specific BIOS attributes and actions for changing the BIOS settings. Changes to the BIOS typically require a system reset before they take effect. | C7: =Profile!AP9 -> 0 | D7: =IF(Profile!C7="Profile",IF(Profile!A9="ResourceRequirement","OK","XXX"),"XXX") -> XXX | G7: 425 | H7: ProcessorMetrics (1.0.0) | I7: 48 | J7: OK
A8: =ROW() -> 8 | B8: =Profile!A8 -> Table 9: O-PAS Profile Map for the Redfish Bios Resource | C8: =Profile!AP10 -> 0 | D8: =IF(Profile!C8="Profile",IF(Profile!A10="ResourceRequirement","OK","XXX"),"XXX") -> XXX | G8: 472 | H8: SimpleStorage (1.2.2) | I8: 56 | J8: OK
A9: =ROW() -> 9 | B9: =Profile!A9 -> Bios (1.0.4) | C9: =Profile!AP11 -> 0 | D9: =IF(Profile!C9="Profile",IF(Profile!A11="ResourceRequirement","OK","XXX"),"XXX") -> XXX | G9: 500 | H9: Storage (1.7.0) | I9: 58 | J9: OK
A10: =ROW() -> 10 | B10: =Profile!A10 -> 0 | C10: =Profile!AP12 -> 0 | D10: =IF(Profile!C10="Profile",IF(Profile!A12="ResourceRequirement","OK","XXX"),"XXX") -> XXX | G10: 566 | H10: Volume (1.0.3) | I10: 67 | J10: OK
A11: =ROW() -> 11 | B11: =Profile!A11 -> Bios (1.0.6) | C11: =Profile!AP13 -> 4 | D11: =IF(Profile!C11="Profile",IF(Profile!A13="ResourceRequirement","OK","XXX"),"XXX") -> OK | G11: 628 | H11: EventDestination (1.5.0) | I11: 18 | J11: OK
A12: =ROW() -> 12 | B12: =Profile!A12 -> 0 | C12: =Profile!AP14 -> 0 | D12: =IF(Profile!C12="Profile",IF(Profile!A14="ResourceRequirement","OK","XXX"),"XXX") -> XXX | G12: 657 | H12: EventService (1.3.0) | I12: 19 | J12: OK
... A67: =ROW() -> 67 | B67: =Profile!A67 -> Certificates | C67: =Profile!AP69 -> 0 | D67: =IF(Profile!C67="Profile",IF(Profile!A69="ResourceRequirement","OK","XXX"),"XXX") -> XXX | G67: 3683 | H67: DCNNonOpasIOSubsystem (1.0.0) | I67: 13 | J67: OK
A68: =ROW() -> 68 | B68: =Profile!A68 -> @odata.id | C68: =Profile!AP70 -> 0 | D68: =IF(Profile!C68="Profile",IF(Profile!A70="ResourceRequirement","OK","XXX"),"XXX") -> XXX
A69: =ROW() -> 69 | B69: =Profile!A69 -> EthernetInterfaces | C69: =Profile!AP71 -> 0 | D69: =IF(Profile!C69="Profile",IF(Profile!A71="ResourceRequirement","OK","XXX"),"XXX") -> XXX
A70: =ROW() -> 70 | B70: =Profile!A70 -> @odata.id | C70: =Profile!AP72 -> 0 | D70: =IF(Profile!C70="Profile",IF(Profile!A72="ResourceRequirement","OK","XXX"),"XXX") -> XXX
A71: =ROW() -> 71 | B71: =Profile!A71 -> HostedServices | C71: =Profile!AP73 -> 0 | D71: =IF(Profile!C71="Profile",IF(Profile!A73="ResourceRequirement","OK","XXX"),"XXX") -> XXX
A72: =ROW() -> 72 | B72: =Profile!A72 -> Oem | C72: =Profile!AP74 -> 0 | D72: =IF(Profile!C72="Profile",IF(Profile!A74="ResourceRequirement","OK","XXX"),"XXX") -> XXX
A73: =ROW() -> 73 | B73: =Profile!A73 -> StorageServices | C73: =Profile!AP75 -> 0 | D73: =IF(Profile!C73="Profile",IF(Profile!A75="ResourceRequirement","OK","XXX"),"XXX") -> XXX
A74: =ROW() -> 74 | B74: =Profile!A74 -> DistributedControlNodeServices | C74: =Profile!AP76 -> 0 | D74: =IF(Profile!C74="Profile",IF(Profile!A76="ResourceRequirement","OK","XXX"),"XXX") -> XXX
A75: =ROW() -> 75 | B75: =Profile!A75 -> @odata.id | C75: =Profile!AP77 -> 0 | D75: =IF(Profile!C75="Profile",IF(Profile!A77="ResourceRequirement","OK","XXX"),"XXX") -> XXX
A76: =ROW() -> 76 | B76: =Profile!A76 -> HostingRoles | C76: =Profile!AP78 -> 0 | D76: =IF(Profile!C76="Profile",IF(Profile!A78="ResourceRequirement","OK","XXX"),"XXX") -> XXX
A77: =ROW() -> 77 | B77: =Profile!A77 -> HostName | C77: =Profile!AP79 -> 0 | D77: =IF(Profile!C77="Profile",IF(Profile!A79="ResourceRequirement","OK","XXX"),"XXX") -> XXX
A78: =ROW() -> 78 | B78: =Profile!A78 -> HostWatchdogTimer | C78: =Profile!AP80 -> 0 | D78: =IF(Profile!C78="Profile",IF(Profile!A80="ResourceRequirement","OK","XXX"),"XXX") -> XXX
A79: =ROW() -> 79 | B79: =Profile!A79 -> FunctionEnabled | C79: =Profile!AP81 -> 0 | D79: =IF(Profile!C79="Profile",IF(Profile!A81="ResourceRequirement","OK","XXX"),"XXX") -> XXX
A80: =ROW() -> 80 | B80: =Profile!A80 -> Oem | C80: =Profile!AP84 -> 0 | D80: =IF(Profile!C80="Profile",IF(Profile!A84="ResourceRequirement","OK","XXX"),"XXX") -> XXX
A81: =ROW() -> 81 | B81: =Profile!A81 -> Status | C81: =Profile!AP85 -> 0 | D81: =IF(Profile!C81="Profile",IF(Profile!A85="ResourceRequirement","OK","XXX"),"XXX") -> XXX
A82: =ROW() -> 82 | B82: =Profile!A84 -> TimeoutAction | C82: =Profile!AP87 -> 0 | D82: =IF(Profile!C84="Profile",IF(Profile!A87="ResourceRequirement","OK","XXX"),"XXX") -> XXX
A83: =ROW() -> 83 | B83: =Profile!A85 -> WarningAction | C83: =Profile!AP88 -> 0 | D83: =IF(Profile!C85="Profile",IF(Profile!A88="ResourceRequirement","OK","XXX"),"XXX") -> XXX
A84: =ROW() -> 84 | B84: =Profile!A87 -> LocationIndicatorActive | C84: =Profile!AP89 -> 0 | D84: =IF(Profile!C87="Profile",IF(Profile!A89="ResourceRequirement","OK","XXX"),"XXX") -> XXX
A85: =ROW() -> 85 | B85: =Profile!A88 -> Links | C85: =Profile!AP90 -> 0 | D85: =IF(Profile!C88="Profile",IF(Profile!A90="ResourceRequirement","OK","XXX"),"XXX") -> XXX
A86: =ROW() -> 86 | B86: =Profile!A89 -> Chassis | C86: =Profile!AP91 -> 0 | D86: =IF(Profile!C89="Profile",IF(Profile!A91="ResourceRequirement","OK","XXX"),"XXX") -> XXX
A87: =ROW() -> 87 | B87: =Profile!A90 -> @odata.id | C87: =Profile!AP92 -> 0 | D87: =IF(Profile!C90="Profile",IF(Profile!A92="ResourceRequirement","OK","XXX"),"XXX") -> XXX
A88: =ROW() -> 88 | B88: =Profile!A91 -> ConsumingComputerSystems | C88: =Profile!AP93 -> 0 | D88: =IF(Profile!C91="Profile",IF(Profile!A93="ResourceRequirement","OK","XXX"),"XXX") -> XXX
A89: =ROW() -> 89 | B89: =Profile!A92 -> @odata.id | C89: =Profile!AP94 -> 0 | D89: =IF(Profile!C92="Profile",IF(Profile!A94="ResourceRequirement","OK","XXX"),"XXX") -> XXX
A90: =ROW() -> 90 | B90: =Profile!A93 -> CooledBy | C90: =Profile!AP95 -> 0 | D90: =IF(Profile!C93="Profile",IF(Profile!A95="ResourceRequirement","OK","XXX"),"XXX") -> XXX
A91: =ROW() -> 91 | B91: =Profile!A94 -> @odata.id | C91: =Profile!AP96 -> 0 | D91: =IF(Profile!C94="Profile",IF(Profile!A96="ResourceRequirement","OK","XXX"),"XXX") -> XXX
A92: =ROW() -> 92 | B92: =Profile!A95 -> Endpoints | C92: =Profile!AP97 -> 0 | D92: =IF(Profile!C95="Profile",IF(Profile!A97="ResourceRequirement","OK","XXX"),"XXX") -> XXX
A93: =ROW() -> 93 | B93: =Profile!A96 -> @odata.id | C93: =Profile!AP98 -> 0 | D93: =IF(Profile!C96="Profile",IF(Profile!A98="ResourceRequirement","OK","XXX"),"XXX") -> XXX
A94: =ROW() -> 94 | B94: =Profile!A97 -> ManagedBy | C94: =Profile!AP99 -> 0 | D94: =IF(Profile!C97="Profile",IF(Profile!A99="ResourceRequirement","OK","XXX"),"XXX") -> XXX
...

Sheet Sheet3
A1: TrustedComponent 1.1.0 | B1: The TrustedComponent resource represents a trusted device, such as a TPM.
A2: Certificates | B2: The link to a collection of device identity certificates of the trusted component. Contains a link to a resource.
A3: @odata.id | B3: Link to Collection of Certificate. See the Certificate schema for details.
A4: FirmwareVersion | B4: The software version of the active software image on the trusted component.
A5: Links | B5: The links to other resources that are related to this resource.
A6: ActiveSoftwareImage | B6: The link to the software inventory resource that represents the active firmware image for this trusted component. See the SoftwareInventory schema for details on this property.
A7: @odata.id string read-write Link to a SoftwareInventory resource. See the Links section and the SoftwareInventory schema for details.
A8: ComponentIntegrity | B8: An array of links to ComponentIntegrity resources for which the trusted component is responsible.
A9: @odata.id | B9: Link to a ComponentIntegrity resource. See the Links section and the ComponentIntegrity schema for details.
A10: ComponentsProtected | B10: An array of links to resources that the target component protects.
A11: @odata.id | B11: The unique identifier for a resource.
A12: IntegratedInto | B12: A link to a resource to which this trusted component is integrated.
A13: @odata.id | B13: The unique identifier for a resource.
A14: Oem | B14: See the Oem object definition in the Common properties section.
A15: SoftwareImages | B15: The images that are associated with this trusted component.
A16: @odata.id | B16: Link to a SoftwareInventory resource. See the Links section and the SoftwareInventory schema for details.
A17: Manufacturer | B17: The manufacturer of this trusted component.
A18: Model | B18: The model number of the trusted component.
A19: PartNumber | B19: The part number of the trusted component.
... A49: RequestedWatts | B49: The potential power, in watts, that the subsystem requests, which might be higher than the current level being consumed because the requested power includes a budget that the subsystem wants for future use.
A50: Batteries | B50: The link to the collection of batteries within this subsystem. See the Battery schema for details. | C50: (v1.1+)
A51: @odata.id | B51: Link to Collection of Battery
A52: CapacityWatts | B52: The total amount of power that can be allocated to this subsystem. This value can be either the power supply capacity or the power budget that an upstream chassis assigns to this subsystem.
A53: PowerSupplies | B53: The link to the collection of power supplies within this subsystem.
A54: @odata.id | B54: Link to Collection of PowerSupply. See the PowerSupply schema for details.
A55: PowerSupplyRedundancy | B55: The redundancy information for the set of power supplies in this subsystem.
A56: MaxSupportedInGroup | B56: The maximum number of devices supported in this redundancy group. (v1.4+)
A57: MinNeededInGroup | B57: The minimum number of devices needed for this group to be redundant. (v1.4+)
A58: RedundancyGroup | B58: The links to the devices included in this redundancy group.
A59: @odata.id | B59: The unique identifier for a resource. (v1.4+)
A60: RedundancyType | B60: The redundancy mode of the group. For the possible property values, see RedundancyType in Property details. (v1.4+)
A61: Status | B61: The status and health of the resource and its subordinate or dependent resources. (v1.4+)
A62: Conditions | B62: Conditions in this resource that require attention. (v1.11+)
... A93: Links | B93: The links to other resources that are related to this resource.
A94: Oem See the Oem object definition in the Common properties section.
A95: Outlet | B95: A link to the outlet connected to this power supply. See the Outlet schema for details on this property. Deprecated in v1.4 and later. This property has been deprecated in favor of the PowerOutlets property to allow for consistent modeling of power supplies with multiple outlet support. (deprecated v1.4)
A96: @odata.id | B96: Link to an Outlet resource. See the Links section and the Outlet schema for details.
A97: PoweringChassis | B97: An array of links to the chassis that are directly powered by this power supply. (v1.4+)
A98: @odata.id | B98: Link to a Chassis resource. See the Links section and the Chassis schema for details.
A99: PowerOutlets | B99: Link to a Outlet resource. See the Links section and the Outlet schema for details. (v1.2+)
...
